Workbook

Sheet DADOS
A1: 46036 | B1: LISTA 01 - STB | G1: 310 | H1: =VLOOKUP(G1,Apoio!A$1:B26,2,0) -> GEKA
B2: PEÇA | D2: STATUS DE FABRICAÇÃO
A3: OP | B3: CÓDIGO | C3: QTD | D3: =IFERROR(VLOOKUP(G1,Apoio!F$1:G$43,2,0),"") -> GEKA | E3: DATA | F3: =IFERROR(VLOOKUP(G1,Apoio!H$1:I$44,2,0),"") | G3: DATA | H3: CONF. ENTREGA
A4: 7448266 | B4: 30500440 | C4: 28 | D4: OK MAICON | E4: 46043 | F4: =IF($A4<>"",IF($F3="","DIRETO",""),"") -> DIRETO | G4: =IF(F4="DIRETO","-","") -> - | H4: OK
A5: 7448267 | B5: 30500463-1 | C5: 14 | D5: OK MAICON | E5: 46038 | F5: =IF($A5<>"",IF($F3="","DIRETO",""),"") -> DIRETO | G5: =IF(F5="DIRETO","-","") -> - | H5: OK
A6: 7448268 | B6: 30500465 | C6: 10 | D6: MENOTTI PEDE | E6: - | F6: =IF($A6<>"",IF($F3="","DIRETO",""),"") -> DIRETO | G6: =IF(F6="DIRETO","-","") -> - | H6: OK | J6: =VLOOKUP(G1,Apoio!A$1:B26,2,0) -> GEKA | N6: GERAL
A7: 7448269 | B7: 30500468-1 | C7: 23 | D7: OK MAICON | E7: 46043 | F7: =IF($A7<>"",IF($F3="","DIRETO",""),"") -> DIRETO | G7: =IF(F7="DIRETO","-","") -> - | H7: OK | J7: TOTAL DE OPS | N7: TOTAL DE ORDENS DE PRODUÇÃO
A8: 7448270 | B8: 30500501 | C8: 14 | D8: OK MAICON | E8: 46043 | F8: =IF($A8<>"",IF($F3="","DIRETO",""),"") -> DIRETO | G8: =IF(F8="DIRETO","-","") -> - | H8: OK | J8: =COUNTIF(A4:A18,">7000000") -> 12 | N8: =COUNTIF(A:A,">7000000") -> 219
A9: 7448271 | B9: 30500510-1 | C9: 14 | D9: OK MAICON | E9: 46038 | F9: =IF($A9<>"",IF($F3="","DIRETO",""),"") -> DIRETO | G9: =IF(F9="DIRETO","-","") -> - | H9: OK | J9: OPS FINALIZADAS | N9: TOTAL DE ORDENS FINALIZADAS
A10: 7448272 | B10: 30500518-3 | C10: 7 | D10: OK MAICON | E10: 46038 | F10: =IF($A10<>"",IF($F3="","DIRETO",""),"") -> DIRETO | G10: =IF(F10="DIRETO","-","") -> - | H10: OK | J10: =COUNTIF(H4:H18,"ok*") -> 12 | N10: =COUNTIF(H:H,"ok*") -> 206
A11: 7448273 | B11: 30500544 | C11: 7 | D11: OK MAICON | E11: 46043 | F11: =IF($A11<>"",IF($F3="","DIRETO",""),"") -> DIRETO | G11: =IF(F11="DIRETO","-","") -> - | H11: OK | J11: PORCENTAGEM | N11: ESTÁGIO ATUAL
A12: 7448274 | B12: 30500551-1 | C12: 14 | D12: OK MAICON | E12: 46038 | F12: =IF($A12<>"",IF($F3="","DIRETO",""),"") -> DIRETO | G12: =IF(F12="DIRETO","-","") -> - | H12: OK | J12: =J10/J8 -> 1 | N12: =N10/N8 -> 0.94063927
A13: 7448275 | B13: 30500552 | C13: 14 | D13: OK MAICON | E13: 46042 | F13: USINAGEM | G13: 46042 | H13: OK
A14: 7448276 | B14: 30502300-1 | C14: 8 | D14: OK MAICON | E14: 46038 | F14: =IF($A14<>"",IF($F3="","DIRETO",""),"") -> DIRETO | G14: =IF(F14="DIRETO","-","") -> - | H14: OK
A15: 46036 | B15: LISTA 01 - STB | G15: 310 | H15: =VLOOKUP(G15,Apoio!A$1:B40,2,0) -> GEKA
B16: PEÇA | D16: STATUS DE FABRICAÇÃO
A17: OP | B17: CÓDIGO | C17: QTD | D17: =IFERROR(VLOOKUP(G15,Apoio!F$1:G$43,2,0),"") -> GEKA | E17: DATA | F17: =IFERROR(VLOOKUP(G15,Apoio!H$1:I$44,2,0),"") | G17: DATA | H17: CONF. ENTREGA
A18: 7448277 | B18: 30502387 | C18: 7 | D18: OK MATEUS | E18: 46038 | F18: =IF($A18<>"",IF($F17="","DIRETO",""),"") -> DIRETO | G18: =IF(F18="DIRETO","-","") -> - | H18: OK
F19: =IF($A19<>"",IF($F17="","DIRETO",""),"") | G19: =IF(F19="DIRETO","-","")
F20: =IF($A20<>"",IF($F17="","DIRETO",""),"") | G20: =IF(F20="DIRETO","-","")
F21: =IF($A21<>"",IF($F17="","DIRETO",""),"") | G21: =IF(F21="DIRETO","-","")
F22: =IF($A22<>"",IF($F17="","DIRETO",""),"") | G22: =IF(F22="DIRETO","-","")
F23: =IF($A23<>"",IF($F17="","DIRETO",""),"") | G23: =IF(F23="DIRETO","-","")
F24: =IF($A24<>"",IF($F17="","DIRETO",""),"") | G24: =IF(F24="DIRETO","-","")
F25: =IF($A25<>"",IF($F17="","DIRETO",""),"") | G25: =IF(F25="DIRETO","-","")
F26: =IF($A26<>"",IF($F17="","DIRETO",""),"") | G26: =IF(F26="DIRETO","-","")
F27: =IF($A27<>"",IF($F17="","DIRETO",""),"") | G27: =IF(F27="DIRETO","-","")
F28: =IF($A28<>"",IF($F17="","DIRETO",""),"") | G28: =IF(F28="DIRETO","-","")
A29: 46036 | B29: LISTA 01 - STB | G29: 311 | H29: =VLOOKUP(G29,Apoio!A$1:B54,2,0) -> GEKA/DOBRA
B30: PEÇA | D30: STATUS DE FABRICAÇÃO
A31: OP | B31: CÓDIGO | C31: QTD | D31: =IFERROR(VLOOKUP(G29,Apoio!F$1:G$43,2,0),"") -> GEKA | E31: DATA | F31: =IFERROR(VLOOKUP(G29,Apoio!H$1:I$44,2,0),"") -> DOBRA | G31: DATA | H31: CONF. ENTREGA
A32: 7448278 | B32: 30500130 | C32: 14 | D32: OK MAICON | E32: 46038 | F32: OK | G32: 46043 | H32: OK
A33: 7448279 | B33: 30500117 | C33: 14 | D33: OK MAICON | E33: 46038 | F33: OK | G33: 46044 | H33: OK
A34: 7448280 | B34: 30500442 | C34: 42 | D34: OK MAICON | E34: 46038 | F34: OK | G34: 46043 | H34: OK | J34: =VLOOKUP(G29,Apoio!A$1:B54,2,0) -> GEKA/DOBRA
A35: 7448281 | B35: 30500462 | C35: 14 | D35: OK MAICON | E35: 46038 | F35: OK | G35: 46043 | H35: OK | J35: TOTAL DE OPS
F36: =IF($A36<>"",IF($F31="","DIRETO",""),"") | G36: =IF(F36="DIRETO","-","") | J36: =COUNTIF(A32:A42,">7000000") -> 4
F37: =IF($A37<>"",IF($F31="","DIRETO",""),"") | G37: =IF(F37="DIRETO","-","") | J37: OPS FINALIZADAS
F38: =IF($A38<>"",IF($F31="","DIRETO",""),"") | G38: =IF(F38="DIRETO","-","") | J38: =COUNTIF(H32:H42,"ok*") -> 4
F39: =IF($A39<>"",IF($F31="","DIRETO",""),"") | G39: =IF(F39="DIRETO","-","") | J39: PORCENTAGEM
F40: =IF($A40<>"",IF($F31="","DIRETO",""),"") | G40: =IF(F40="DIRETO","-","") | J40: =J38/J36 -> 1
...

Sheet Apoio
A1: 310 | B1: GEKA | F1: 311 | G1: GEKA | H1: 311 | I1: DOBRA
A2: 311 | B2: GEKA/DOBRA | F2: 310 | G2: GEKA | H2: 312 | I2: USINAGEM
A3: 312 | B3: GEKA/USINAGEM | F3: 312 | G3: GEKA | H3: 321 | I3: DOBRA
A4: 320 | B4: GUILHOTINA | F4: 320 | G4: GUILHOTINA | H4: 331 | I4: DOBRA
A5: 321 | B5: GUILHOTINA/DOBRA | F5: 321 | G5: GUILHOTINA | H5: 351 | I5: USINAGEM
A6: 330 | B6: LASER 6KW | F6: 330 | G6: LASER 6KW | H6: 352 | I6: DOBRA
A7: 331 | B7: LASER 6KW/DOBRA | F7: 331 | G7: LASER 6KW | H7: 361 | I7: USINAGEM
A8: 350 | B8: LASER 40KW | F8: 350 | G8: LASER 40KW | H8: 362 | I8: DOBRA
A9: 351 | B9: LASER 40KW/USINAGEM | F9: 351 | G9: LASER 40KW
A10: 352 | B10: LASER 40KW/DOBRA | F10: 352 | G10: LASER 40KW
A11: 360 | B11: SERRA | F11: 360 | G11: SERRA
A12: 361 | B12: SERRA/USINAGEM | F12: 361 | G12: SERRA
A13: 362 | B13: SERRA/DOBRA | F13: 362 | G13: SERRA
A14: 370 | B14: USINAGEM | F14: 370 | G14: USINAGEM
